Workbook

Sheet Sheet1
A2: 序号 | B2: 农户姓名 | C2: 组别 | D2: 地块名称 | E2: 土块类型（田或土） | F2: 地块面积（亩） | G2: 单价（元） | H2: 金额（元） | I2: 农户签字 | J2: 备注
A3: 3 | B3: 郑茂清 | C3: 9组 | D3: 羊场背后 | E3: 土 | F3: 0.1 | G3: 380 | H3: =G3*F3 -> 38 | J3: 9.25
A4: 4 | B4: 游建华 | C4: 9组 | D4: 羊场背后 | E4: 土 | F4: 0.08 | G4: 380 | H4: =G4*F4 -> 30.4 | J4: 9.25
A5: 5 | B5: 汤菊珍 | C5: 9组 | D5: 羊场背后 | E5: 土 | F5: 0.13 | G5: 380 | H5: =G5*F5 -> 49.4 | J5: 9.25
A6: 6 | B6: 魏菊明 | C6: 9组 | D6: 羊场背后 | E6: 土 | F6: 0.2 | G6: 380 | H6: =G6*F6 -> 76 | J6: 9.25
A7: 7 | B7: 程勇军 | C7: 9组 | D7: 羊场背后 | E7: 土 | F7: 0.19 | G7: 380 | H7: =G7*F7 -> 72.2 | J7: 9.25
A8: 8 | B8: 熊树权 | C8: 9组 | D8: 羊场背后 | E8: 土 | F8: 0.33 | G8: 380 | H8: =G8*F8 -> 125.4 | J8: 9.25
A9: 9 | B9: 夏治安 | C9: 9组 | D9: 羊场背后 | E9: 土 | F9: 0.11 | G9: 380 | H9: =G9*F9 -> 41.8 | J9: 9.25
A10: 12 | B10: 夏明扬 | C10: 10组 | E10: 田 | F10: 0.38 | G10: 480 | H10: =G10*F10 -> 182.4 | J10: 9.5 | K10: 自种
A11: 30 | B11: 林柱根 | C11: 10组 | E11: 田 | F11: 0.5 | G11: 480 | H11: =G11*F11 -> 240 | J11: 9.5 | K11: 已签
A12: 33 | B12: 林立平 | C12: 10组 | E12: 田 | F12: 1.03 | G12: 480 | H12: =G12*F12 -> 494.4 | J12: 9.5
A13: 60 | B13: 王金文 | C13: 10组 | E13: 田 | F13: 1.56 | G13: 480 | H13: =G13*F13 -> 748.8 | J13: 9.8
A14: 61 | B14: 邦田 | C14: 10组 | E14: 田 | G14: 480 | H14: =G14*F14 -> 0 | J14: 9.8
A15: 62 | B15: 王守刚 | C15: 10组 | E15: 田 | F15: 1.62 | G15: 480 | H15: =G15*F15 -> 777.6 | J15: 9.8 | K15: 已签
A16: 63 | B16: 王述文 | C16: 10组 | E16: 田 | F16: 0.81 | G16: 480 | H16: =G16*F16 -> 388.8 | J16: 9.8 | K16: 已签
A17: 64 | B17: 王云成 | C17: 10组 | E17: 土 | F17: 1.05 | G17: 380 | H17: =G17*F17 -> 399 | J17: 9.8
A18: 66 | B18: 林德江 | C18: 10组 | E18: 土 | F18: 0.12 | G18: 380 | H18: =G18*F18 -> 45.6 | J18: 9.8 | K18: 已签
A19: 67 | B19: 林德民 | C19: 10组 | E19: 土 | F19: 0.93 | G19: 380 | H19: =G19*F19 -> 353.4 | J19: 9.8 | K19: 已签
A20: 68 | B20: 林自明 | C20: 10组 | E20: 土 | F20: 0.25 | G20: 380 | H20: =G20*F20 -> 95 | J20: 9.8 | K20: 已签
A21: 69 | B21: 林伟 | C21: 10组 | E21: 土 | F21: 0.85 | G21: 380 | H21: =G21*F21 -> 323 | J21: 9.8
B22: 林柱军 | C22: 10组 | E22: 田 | F22: 0.3
B23: 林聪 | C23: 10组 | E23: 田 | F23: 0.4
A24: 70 | B24: 林柱根 | C24: 10组 | E24: 土 | F24: 0.36 | G24: 380 | H24: =G24*F24 -> 136.8 | J24: 9.8 | K24: 已签
A25: 71 | B25: 林伟 | C25: 10组 | E25: 土 | F25: 0.35 | G25: 380 | H25: =G25*F25 -> 133 | J25: 9.8
A26: 72 | B26: 林自明 | C26: 10组 | E26: 土 | F26: 0.2 | G26: 380 | H26: =G26*F26 -> 76 | J26: 9.8 | K26: 已签
A27: 73 | B27: 申书华 | C27: 10组 | E27: 土 | F27: 0.17 | G27: 380 | H27: =G27*F27 -> 64.6 | J27: 9.8 | K27: 已签
A28: 74 | B28: 林德昆 | C28: 10组 | E28: 土 | F28: 0.16 | G28: 380 | H28: =G28*F28 -> 60.8 | J28: 9.8 | K28: 已签
A29: 75 | B29: 林德江 | C29: 10组 | E29: 土 | F29: 0.09 | G29: 380 | H29: =G29*F29 -> 34.2 | J29: 9.8 | K29: 已签
A30: 76 | B30: 王金文 | C30: 10组 | E30: 田 | F30: 1.42 | G30: 480 | H30: =G30*F30 -> 681.6 | J30: 9.8
A31: 77 | B31: 王仲良 | C31: 10组 | E31: 田 | F31: 1.36 | G31: 480 | H31: =G31*F31 -> 652.8 | J31: 9.8
A32: 78 | B32: 王九明 | C32: 10组 | E32: 田 | F32: 0.73 | G32: 480 | H32: =G32*F32 -> 350.4 | J32: 9.8
A33: 79 | B33: 王守智 | C33: 10组 | E33: 田 | F33: 0.78 | G33: 480 | H33: =G33*F33 -> 374.4 | J33: 9.8 | K33: 已签
A34: 80 | B34: 王子根 | C34: 10组 | E34: 田 | F34: 0.24 | G34: 480 | H34: =G34*F34 -> 115.2 | J34: 9.8 | K34: 已签
A35: 81 | B35: 王述文 | C35: 10组 | E35: 田 | F35: 0.23 | G35: 480 | H35: =G35*F35 -> 110.4 | J35: 9.8 | K35: 已签
A36: 82 | B36: 王守潮 | C36: 10组 | E36: 田 | F36: 0.79 | G36: 480 | H36: =G36*F36 -> 379.2 | J36: 9.8 | K36: 已签
A37: 83 | B37: 夏明扬 | C37: 10组 | E37: 田 | F37: 0.26 | G37: 480 | H37: =G37*F37 -> 124.8 | J37: 9.8 | K37: 自种
A38: 84 | B38: 郑东秀 | C38: 10组 | E38: 田 | F38: 0.37 | G38: 480 | H38: =G38*F38 -> 177.6 | J38: 9.8 | K38: 已签
A39: 85 | B39: 王志军 | C39: 10组 | E39: 田 | F39: 0.28 | G39: 480 | H39: =G39*F39 -> 134.4 | J39: 9.8
A40: 86 | B40: 王仲良 | C40: 10组 | E40: 土 | F40: 0.09 | G40: 380 | H40: =G40*F40 -> 34.2 | J40: 9.8
A41: 87 | B41: 夏明扬 | C41: 10组 | E41: 田 | F41: 0.34 | G41: 380 | H41: =G41*F41 -> 129.2 | J41: 9.8 | K41: 自种
...

Sheet 12组
A1: 黄羊种养殖循环项目土地丈量表
A2: 序号 | B2: 农户姓名 | C2: 组别 | D2: 地块名称 | E2: 土块类型（田或土） | F2: 地块面积（亩） | G2: 单价（元） | H2: 金额（元） | I2: 农户签字 | J2: 备注
A3: 1 | B3: 王会永 | C3: 12组 | D3: 大方田 | E3: 田 | F3: 1.43 | G3: 480 | H3: 686.4 | J3: 9.29 | K3: 已签
A4: 2 | B4: 王德明 | C4: 12组 | D4: 大方田 | E4: 田 | F4: 0.81 | G4: 480 | H4: 388.8 | J4: 9.29 | K4: 已签
A5: 3 | B5: 王怡梅 | C5: 12组 | D5: 区木树田 | E5: 田 | F5: 1.26 | G5: 480 | H5: 604.8 | J5: 9.29
A6: 4 | B6: 王德明 | C6: 12组 | D6: 区木树田 | E6: 田 | F6: 0.58 | G6: 480 | H6: 278.4 | J6: 9.29 | K6: 已签
A7: 5 | B7: 王敏均 | C7: 12组 | D7: 区木树田 | E7: 田 | F7: 0.79 | G7: 480 | H7: 379.2 | J7: 9.29
A8: 6 | B8: 李雪花 | C8: 12组 | D8: 区木树田 | E8: 田 | F8: 1.58 | G8: 480 | H8: 758.4 | J8: 9.29 | K8: 已签
A9: 7 | B9: 向功明 | C9: 12组 | D9: 枇杷田 | E9: 田 | F9: 0.19 | G9: 480 | H9: 91.2 | J9: 9.29 | K9: 已签
A10: 8 | B10: 汤建均（68） | C10: 12组 | D10: 幺堰河边 | E10: 田 | F10: 0.69 | G10: 480 | H10: 331.2 | J10: 9.29 | K10: 已签
A11: 9 | B11: 王敏江 | C11: 12组 | D11: 河边田 | E11: 田 | F11: 0.42 | G11: 480 | H11: 201.6 | J11: 9.29 | K11: 已签
A12: 10 | B12: 王敏均 | C12: 12组 | D12: 河边田 | E12: 田 | F12: 0.28 | G12: 480 | H12: 134.4 | J12: 9.29
A13: 11 | B13: 汤火明（小） | C13: 12组 | D13: 大方田 | E13: 田 | F13: 0.47 | G13: 480 | H13: 225.6 | J13: 9.29 | K13: 已签
A14: 12 | B14: 汤火明（小） | C14: 12组 | D14: 和尚田 | E14: 田 | F14: 0.5 | G14: 480 | H14: 240 | J14: 9.29 | K14: 已签
A15: 13 | B15: 王敏江 | C15: 12组 | D15: 花果树田 | E15: 田 | F15: 0.78 | G15: 480 | H15: 374.4 | J15: 9.29 | K15: 已签
A16: 14 | B16: 向功明 | C16: 12组 | D16: 花果树田 | E16: 田 | F16: 0.75 | G16: 480 | H16: 360 | J16: 9.29 | K16: 已签
A17: 15 | B17: 向功明 | C17: 12组 | D17: 花果树田 | E17: 田 | F17: 0.28 | G17: 480 | H17: 134.4 | J17: 9.29 | K17: 已签
A18: 16 | B18: 王会永 | C18: 12组 | D18: 花果树田 | E18: 田 | F18: 0.31 | G18: 480 | H18: 148.8 | J18: 9.29 | K18: 已签
A19: 17 | B19: 程群林 | C19: 12组 | D19: 榜榜田 | E19: 田 | F19: 0.82 | G19: 480 | H19: 316.8 | J19: 9.29 | K19: 已签
A20: 18 | B20: 汤火明（小） | C20: 12组 | D20: 榜榜田 | E20: 田 | F20: 0.3 | G20: 480 | H20: 144 | J20: 9.29 | K20: 已签
A21: 19 | B21: 王会永 | C21: 12组 | D21: 下榜榜田 | E21: 田 | F21: 0.45 | G21: 480 | H21: 216 | J21: 9.29 | K21: 已签
A22: 20 | B22: 王会明 | C22: 12组 | D22: 长田坝 | E22: 田 | F22: 0.49 | G22: 480 | H22: 235.2 | J22: 9.29 | K22: 已签
A23: 21 | B23: 王怡梅 | C23: 12组 | D23: 长田坝 | E23: 田 | F23: 0.53 | G23: 480 | H23: 254.4 | J23: 9.29
A24: 22 | B24: 汤建均（68） | C24: 12组 | D24: 长田坝 | E24: 田 | F24: 0.36 | G24: 480 | H24: 172.8 | J24: 9.29 | K24: 已签
A25: 23 | B25: 汤火明（小） | C25: 12组 | D25: 长田坝 | E25: 田 | F25: 0.36 | G25: 480 | H25: 172.8 | J25: 9.29 | K25: 已签
A26: 25 | B26: 王建国 | C26: 12组 | D26: 黄紧坡地 | E26: 土 | F26: 0.35 | G26: 380 | H26: 133 | J26: 9.29 | K26: 已签
A27: 26 | B27: 李雪花 | C27: 12组 | D27: 黄紧坡地 | E27: 土 | F27: 0.17 | G27: 380 | H27: 64.6 | J27: 9.29 | K27: 已签
A28: 27 | B28: 王会永 | C28: 12组 | D28: 顺山地 | E28: 土 | F28: 0.82 | G28: 380 | H28: 311.6 | J28: 9.29 | K28: 已签
A29: 28 | B29: 李雪花 | C29: 12组 | D29: 落堂地 | E29: 土 | F29: 0.5 | G29: 380 | H29: 190 | J29: 9.29 | K29: 已签
A30: 29 | B30: 汤建均（68） | C30: 12组 | D30: 落堂地 | E30: 土 | F30: 0.24 | G30: 380 | H30: 91.2 | J30: 9.29 | K30: 已签
A31: 30 | B31: 王敏均 | C31: 12组 | D31: 落堂地 | E31: 土 | F31: 0.94 | G31: 380 | H31: 357.2 | J31: 9.29
A32: 31 | B32: 王敏江 | C32: 12组 | D32: 顺山地 | E32: 土 | F32: 0.2 | G32: 380 | H32: 76 | J32: 9.29 | K32: 已签
A33: 32 | B33: 王长军 | C33: 12组 | D33: 落堂地 | E33: 土 | F33: 0.42 | G33: 380 | H33: 159.6 | J33: 9.29 | K33: 已签
A34: 33 | B34: 王怡梅 | C34: 12组 | D34: 落堂地 | E34: 土 | F34: 0.85 | G34: 380 | H34: 323 | J34: 9.29
A35: 34 | B35: 向功明 | C35: 12组 | D35: 大方田 | E35: 田 | F35: 0.97 | G35: 480 | H35: 465.6 | J35: 9.29 | K35: 已签
A36: 35 | B36: 王会明 | C36: 12组 | D36: 区木树田 | E36: 田 | F36: 1.16 | G36: 480 | H36: 556.8 | J36: 9.29 | K36: 已签
A37: 36 | B37: 王长军 | C37: 12组 | D37: 区木树田 | E37: 田 | F37: 0.92 | G37: 480 | H37: 441.6 | J37: 9.29 | K37: 已签
A38: 37 | B38: 王敏建 | C38: 12组 | D38: 枇杷田 | E38: 田 | F38: 0.79 | G38: 480 | H38: 379.2 | J38: 9.29
A39: 38 | B39: 王学明 | C39: 12组 | D39: 和尚田 | E39: 田 | F39: 0.33 | G39: 480 | H39: 158.4 | J39: 9.29
A40: 39 | B40: 王长江 | C40: 12组 | D40: 和尚田 | E40: 田 | F40: 1.6 | G40: 480 | H40: 768 | J40: 9.29
...

Sheet 10组
A1: 黄羊种养殖循环项目土地丈量表
A2: 序号 | B2: 农户姓名 | C2: 身份证号码 | D2: 组别 | E2: 土块类型 （田或土） | F2: 地块面积（亩） | G2: 单价 （元） | H2: 金额 （元） | I2: 合计金额 （元） | J2: 农户签字 | K2: 电话
A3: =MAX($A$2:A2)+1 -> 1 | B3: 郑茂钦 | C3: =VLOOKUP(B3,'[1]11组'!$A:$B,2,0) -> #N/A | D3: 9 | E3: 田 | F3: 0.11 | G3: 480 | H3: =G3*F3 -> 52.8 | I3: 178.2 | K3: =VLOOKUP(C3,[1]sheet1中岗村户籍!$C:$I,7,0) -> #N/A
E4: 土 | F4: 0.33 | G4: 380 | H4: =G4*F4 -> 125.4 | K4: =VLOOKUP(C4,[1]sheet1中岗村户籍!$C:$I,7,0) -> #N/A
A5: =MAX($A$2:A3)+1 -> 2 | B5: 程勇军 | C5: =VLOOKUP(B5,'[1]11组'!$A:$B,2,0) -> #N/A | D5: 9 | E5: 田 | F5: 0.52 | G5: 480 | H5: =G5*F5 -> 249.6 | I5: 1578.4 | K5: =VLOOKUP(C5,[1]sheet1中岗村户籍!$C:$I,7,0) -> #N/A
E6: 土 | F6: 0.19 | G6: 380 | H6: =G6*F6 -> 72.2 | K6: =VLOOKUP(C6,[1]sheet1中岗村户籍!$C:$I,7,0) -> #N/A
A7: =MAX($A$2:A5)+1 -> 3 | B7: 林术君 | C7: =VLOOKUP(B7,'[1]11组'!$A:$B,2,0) -> #N/A | D7: 9 | E7: 田 | F7: 0.41 | G7: 480 | H7: =G7*F7 -> 196.8 | I7: 1406.6 | K7: =VLOOKUP(C7,[1]sheet1中岗村户籍!$C:$I,7,0) -> #N/A
E8: 土 | F8: 0.52 | G8: 380 | H8: =G8*F8 -> 197.6 | K8: =VLOOKUP(C8,[1]sheet1中岗村户籍!$C:$I,7,0) -> #N/A
A9: =MAX($A$2:A7)+1 -> 4 | B9: 魏菊明 | C9: =VLOOKUP(B9,'[1]11组'!$A:$B,2,0) -> #N/A | D9: 9 | E9: 土 | F9: 0.55 | G9: 380 | H9: =G9*F9 -> 209 | I9: 209 | K9: =VLOOKUP(C9,[1]sheet1中岗村户籍!$C:$I,7,0) -> #N/A
A10: =MAX($A$2:A9)+1 -> 5 | B10: 夏治安 | C10: =VLOOKUP(B10,'[1]11组'!$A:$B,2,0) -> #N/A | D10: 9 | E10: 土 | F10: 0.11 | G10: 380 | H10: =G10*F10 -> 41.8 | I10: 446.4 | K10: =VLOOKUP(C10,[1]sheet1中岗村户籍!$C:$I,7,0) -> #N/A
A11: =MAX($A$2:A10)+1 -> 6 | B11: 熊树权 | C11: =VLOOKUP(B11,'[1]11组'!$A:$B,2,0) -> #N/A | D11: 9 | E11: 土 | F11: 0.33 | G11: 380 | H11: =G11*F11 -> 125.4 | I11: 307.2 | K11: =VLOOKUP(C11,[1]sheet1中岗村户籍!$C:$I,7,0) -> #N/A
B12: 游文玉 | D12: 9 | E12: 土 | F12: 0.28 | G12: 380 | H12: =G12*F12 -> 106.4 | K12: =VLOOKUP(C12,[1]sheet1中岗村户籍!$C:$I,7,0) -> #N/A
E13: 田 | F13: 0.52 | G13: 480 | H13: =G13*F13 -> 249.6
A14: =MAX($A$2:A12)+1 -> 7 | B14: 郑学文 | C14: =VLOOKUP(B14,'[1]11组'!$A:$B,2,0) -> #N/A | D14: 9 | E14: 田 | F14: 0.45 | G14: 480 | H14: =G14*F14 -> 216 | I14: =H14+#REF! -> #REF! | K14: =VLOOKUP(C14,[1]sheet1中岗村户籍!$C:$I,7,0) -> #N/A
E15: 土 | F15: 0.3 | G15: 380 | H15: =G15*F15 -> 114
B16: 刘桂英 | D16: 9 | E16: 土 | F16: 0.74 | G16: 380 | H16: =G16*F16 -> 281.2 | K16: =VLOOKUP(C16,[1]sheet1中岗村户籍!$C:$I,7,0) -> #N/A
A17: =MAX($A$2:A16)+1 -> 8 | B17: 游建华 | C17: =VLOOKUP(B17,'[1]11组'!$A:$B,2,0) -> #N/A | D17: 10 | E17: 田 | F17: 0.46 | G17: 480 | H17: =G17*F17 -> 220.8 | I17: =H17+#REF! -> #REF! | K17: =VLOOKUP(C17,[1]sheet1中岗村户籍!$C:$I,7,0) -> #N/A
A18: =MAX($A$2:A17)+1 -> 9 | B18: 游建军 | C18: =VLOOKUP(B18,'[1]11组'!$A:$B,2,0) -> #N/A | D18: 10 | E18: 田 | F18: 0.38 | G18: 380 | H18: =G18*F18 -> 144.4 | I18: =H18+#REF! -> #REF! | K18: =VLOOKUP(C18,[1]sheet1中岗村户籍!$C:$I,7,0) -> #N/A
A19: =MAX($A$2:A18)+1 -> 10 | C19: =VLOOKUP(B19,'[1]11组'!$A:$B,2,0) -> #N/A | D19: 10 | E19: 田 | F19: 0.14 | G19: 480 | H19: =G19*F19 -> 67.2 | I19: =H19+#REF! -> #REF! | K19: =VLOOKUP(C19,[1]sheet1中岗村户籍!$C:$I,7,0) -> #N/A
A20: =MAX($A$2:A19)+1 -> 11 | C20: =VLOOKUP(B20,'[1]11组'!$A:$B,2,0) -> #N/A | D20: 10 | E20: 田 | F20: 1.29 | G20: 480 | H20: =G20*F20 -> 619.2 | I20: =H20+#REF! -> #REF! | K20: =VLOOKUP(C20,[1]sheet1中岗村户籍!$C:$I,7,0) -> #N/A
A21: =MAX($A$2:A20)+1 -> 12 | C21: =VLOOKUP(B21,'[1]11组'!$A:$B,2,0) -> #N/A | D21: 10 | E21: 田 | F21: 1.03 | G21: 480 | H21: =G21*F21 -> 494.4 | I21: =H21+H22 -> 787 | K21: =VLOOKUP(C21,[1]sheet1中岗村户籍!$C:$I,7,0) -> #N/A
E22: 土 | F22: 0.77 | G22: 380 | H22: =G22*F22 -> 292.6 | K22: =VLOOKUP(C22,[1]sheet1中岗村户籍!$C:$I,7,0) -> #N/A
A23: =MAX($A$2:A22)+1 -> 13 | C23: =VLOOKUP(B23,'[1]11组'!$A:$B,2,0) -> #N/A | D23: 10 | E23: 田 | F23: 5.88 | G23: 480 | H23: =G23*F23 -> 2822.4 | I23: =H23+H24 -> 4118.2 | K23: =VLOOKUP(C23,[1]sheet1中岗村户籍!$C:$I,7,0) -> #N/A
E24: 土 | F24: 3.41 | G24: 380 | H24: =G24*F24 -> 1295.8 | K24: =VLOOKUP(C24,[1]sheet1中岗村户籍!$C:$I,7,0) -> #N/A
A25: =MAX($A$2:A24)+1 -> 14 | C25: =VLOOKUP(B25,'[1]11组'!$A:$B,2,0) -> #N/A | D25: 10 | E25: 田 | F25: 0.78 | G25: 480 | H25: =G25*F25 -> 374.4 | I25: =H25+#REF! -> #REF! | K25: =VLOOKUP(C25,[1]sheet1中岗村户籍!$C:$I,7,0) -> #N/A
A26: =MAX($A$2:A25)+1 -> 15 | C26: =VLOOKUP(B26,'[1]11组'!$A:$B,2,0) -> #N/A | D26: 10 | E26: 田 | F26: 0.18 | G26: 480 | H26: =G26*F26 -> 86.4 | I26: =H26+H27 -> 90.2 | K26: =VLOOKUP(C26,[1]sheet1中岗村户籍!$C:$I,7,0) -> #N/A
E27: 土 | F27: 0.01 | G27: 380 | H27: =G27*F27 -> 3.8 | K27: =VLOOKUP(C27,[1]sheet1中岗村户籍!$C:$I,7,0) -> #N/A
A28: =MAX($A$2:A27)+1 -> 16 | B28: 王杰 | D28: 10 | E28: 田 | F28: 1.01 | G28: 480 | H28: =G28*F28 -> 484.8 | I28: =H28+#REF! -> #REF! | K28: =VLOOKUP(C28,[1]sheet1中岗村户籍!$C:$I,7,0) -> #N/A
A29: =MAX($A$2:A28)+1 -> 17 | B29: 王云中 | C29: =VLOOKUP(B29,'[1]11组'!$A:$B,2,0) -> #N/A | D29: 10 | E29: 田 | F29: 3.68 | G29: 480 | H29: =G29*F29 -> 1766.4 | I29: =H29+H30 -> 1979.2 | K29: =VLOOKUP(C29,[1]sheet1中岗村户籍!$C:$I,7,0) -> #N/A
E30: 土 | F30: 0.56 | G30: 380 | H30: =G30*F30 -> 212.8 | K30: =VLOOKUP(C30,[1]sheet1中岗村户籍!$C:$I,7,0) -> #N/A
A31: =MAX($A$2:A30)+1 -> 18 | B31: 林伟 | C31: =VLOOKUP(B31,'[1]11组'!$A:$B,2,0) -> #N/A | D31: 10 | E31: 土 | F31: 2.47 | G31: 380 | H31: =G31*F31 -> 938.6 | I31: 938.6 | K31: =VLOOKUP(C31,[1]sheet1中岗村户籍!$C:$I,7,0) -> #N/A
A32: =MAX($A$2:A31)+1 -> 19 | B32: 王耀 | C32: =VLOOKUP(B32,'[1]11组'!$A:$B,2,0) -> #N/A | D32: 10 | E32: 田 | F32: 1.57 | G32: 480 | H32: =G32*F32 -> 753.6 | I32: =H32+H33 -> 772.6 | K32: =VLOOKUP(C32,[1]sheet1中岗村户籍!$C:$I,7,0) -> #N/A
E33: 土 | F33: 0.05 | G33: 380 | H33: =G33*F33 -> 19 | K33: =VLOOKUP(C33,[1]sheet1中岗村户籍!$C:$I,7,0) -> #N/A
A34: =MAX($A$2:A33)+1 -> 20 | B34: 王九明 | C34: =VLOOKUP(B34,'[1]11组'!$A:$B,2,0) -> #N/A | D34: 10 | E34: 田 | F34: 1.24 | G34: 480 | H34: =G34*F34 -> 595.2 | I34: =H34+H35 -> 1047.4 | K34: =VLOOKUP(C34,[1]sheet1中岗村户籍!$C:$I,7,0) -> #N/A
E35: 土 | F35: 1.19 | G35: 380 | H35: =G35*F35 -> 452.2 | K35: =VLOOKUP(C35,[1]sheet1中岗村户籍!$C:$I,7,0) -> #N/A
A36: =MAX($A$2:A35)+1 -> 21 | B36: 王仲良 | C36: =VLOOKUP(B36,'[1]11组'!$A:$B,2,0) -> #N/A | D36: 10 | E36: 田 | F36: 2.65 | G36: 480 | H36: =G36*F36 -> 1272 | I36: 1272 | K36: =VLOOKUP(C36,[1]sheet1中岗村户籍!$C:$I,7,0) -> #N/A
A37: =MAX($A$2:A36)+1 -> 22 | B37: 林柱军 | C37: =VLOOKUP(B37,'[1]11组'!$A:$B,2,0) -> #N/A | D37: 10 | E37: 田 | F37: 0.3 | G37: 480 | H37: =G37*F37 -> 144 | I37: 1276.4 | K37: =VLOOKUP(C37,[1]sheet1中岗村户籍!$C:$I,7,0) -> #N/A
E38: 土 | F38: 2.98 | G38: 380 | H38: =G38*F38 -> 1132.4
A39: =MAX($A$2:A37)+1 -> 23 | B39: 林德平 | C39: =VLOOKUP(B39,'[1]11组'!$A:$B,2,0) -> #N/A | D39: 10 | E39: 土 | F39: 0.85 | G39: 380 | H39: =G39*F39 -> 323 | K39: =VLOOKUP(C39,[1]sheet1中岗村户籍!$C:$I,7,0) -> #N/A
A40: =MAX($A$2:A39)+1 -> 24 | B40: 马丙军 | C40: =VLOOKUP(B40,'[1]11组'!$A:$B,2,0) -> #N/A | D40: 10 | E40: 土 | F40: 0.16 | G40: 380 | H40: =G40*F40 -> 60.8 | I40: 585.2 | K40: =VLOOKUP(C40,[1]sheet1中岗村户籍!$C:$I,7,0) -> #N/A
...
